Workbook

Sheet Database
A1: REFCODE | B1: Formula | C1: Study_ID | D1: Common Name | E1: IUPAC Systematic Name | F1: Other Names | G1: CSD Refcodes | H1: Update Molecules Table | I1: Check CSD | J1: File location | K1: Scientist | L1: Programs | M1: Publication | N1: Date | O1: Update experimental info | P1: Mini document location | Q1: Add Packing coefficients | R1: Find key structures | S1: DFT-D calculations | T1: Upload to database | U1: Download spreadsheet | V1: Motif information? | W1: Date to Github | X1: Github | Y1: Chemiscope | Z1: Number of polymorphs | AA1: Number of structures | AB1: Energy range / kJ mol-1 | AC1: Refcode | AD1: Folder | AE1: Webname | AF1: CommonName | AG1: DateUpdated | AH1: LandscapeSuffixes | AI1: CSD version | AJ1: Formula | AK1: Family | AL1: Searches | AM1: Studies | AN1: PaperSI
A2: ACRDIN | B2: C13 H9 N1 | C2: 0 | D2: Acridine | E2: Acridine | F2: Acridine | G2: ACRDIN04, ACRDIN07, ACRDIN08, ACRDIN02, ACRDIN05, ACRDIN06, ACRDIN12 | H2: Yes | I2: Yes, CSD version 5.44 with Apr 2023 update | J2: \CHEMISTRY_CPOSS\Acridine\ACRDIN_CONDOR | K2: Louise Price / Einat Schur | L2: MOLPAK, DMACRYS_2.0.4 (on CONDOR) | M2: See Study_ID=20 | N2: 2010 | O2: Yes | P2: See Study_ID=20 | Q2: Yes | R2: N/A | S2: N/A | T2: Yes | U2: Yes | W2: wc 10/03/2025 | X2: Acridine_A1 | Y2: Yes | Z2: 6 | AA2: 582 | AB2: 20.42 | AC2: =IF(AND(A2<>A1,T2="Yes"),A2,"") -> ACRDIN | AD2: =AE2 -> Acridine | AE2: =IF(AC2="","",MID(X2,1,(FIND("_",X2))-1)) -> Acridine | AF2: =AE2 -> Acridine | AG2: March2024 | AH2: B2,lines | AI2: =IF(AC2="","",SUBSTITUTE(IF(MID(I2,1,5)="Yes, ",MID(I2,6,100),I2)," ",",")) -> CSD,version,5.44,with,Apr,2023,update | AJ2: =IF(AC2="","",SUBSTITUTE(B2," ",",")) -> C13,H9,N1 | AK2: CPOSS209 | AL2: 2 | AM2: 3 | AN2: =IF(AM2<>"",CONCATENATE(AC2," & \ce{",SUBSTITUTE(AJ2,","," "),"} & ",SUBSTITUTE(AF2,"."," ")," & ",AL2," & ",AM2," \\"),"") -> ACRDIN & \ce{C13 H9 N1} & Acridine & 2 & 3 \\
A3: ACRDIN | B3: C13 H9 N1 | C3: 20 | D3: Acridine | E3: Acridine | F3: Acridine | G3: ACRDIN04, ACRDIN07, ACRDIN08, ACRDIN02, ACRDIN05, ACRDIN06, ACRDIN12 | H3: Yes | I3: Yes, CSD version 5.44 with Apr 2023 update | J3: \CHEMISTRY_CPOSS\Acridine\ACRDIN_CP | K3: Louise Price / Einat Schur (Rui Guo) | L3: CrystalPredictor_v_unknown, DMACRYS_2.0.4 | M3: Schur, E.; Bernstein, J.; Price, L. S.; Guo, R.; Price, S. L.; Lapidus, S. H.; Stephens, P. W., 2019, 9, (18), 4884-4893. | N3: 2010 | O3: Yes | P3: Yes | Q3: Yes | R3: Yes | S3: Rui has done it | T3: Yes | U3: Yes | W3: wc 10/03/2025 | X3: Acridine_B1 | Y3: Yes | Z3: 6 | AA3: 756 | AB3: 10 | AC3: =IF(AND(A3<>A2,T3="Yes"),A3,"") | AE3: =IF(AC3="","",MID(X3,1,(FIND("_",X3))-1)) | AI3: =IF(AC3="","",SUBSTITUTE(IF(MID(I3,1,5)="Yes, ",MID(I3,6,100),I3)," ",",")) | AJ3: =IF(AC3="","",SUBSTITUTE(B3," ",",")) | AN3: =IF(AM3<>"",CONCATENATE(AC3," & ",SUBSTITUTE(AJ3,","," ")," & ",SUBSTITUTE(AF3,"."," ")," & ",AL3," & ",AM3," \\"),"")
A4: ACRDIN | B4: C13 H9 N1 | C4: 21 | D4: Acridine | E4: Acridine | F4: Acridine | G4: ACRDIN04, ACRDIN07, ACRDIN08, ACRDIN02, ACRDIN05, ACRDIN06, ACRDIN12 | H4: Yes | I4: Yes, CSD version 5.44 with Apr 2023 update | J4: \CHEMISTRY_CPOSS\Acridine\ACRDIN_DFT | K4: Louise Price | L4: Study_ID=20, DMACRYS (2.3.1.1) | M4: Database updating paper | N4: 45383 | O4: Yes | P4: See Study_ID=20 | Q4: Yes | R4: Yes | S4: Louise has done it | T4: Yes | U4: Yes | W4: wc 10/03/2025 | X4: Acridine_B2 | Y4: Yes | Z4: 6 | AA4: 755 | AB4: 11.164 | AC4: =IF(AND(A4<>A3,T4="Yes"),A4,"") | AE4: =IF(AC4="","",MID(X4,1,(FIND("_",X4))-1)) | AI4: =IF(AC4="","",SUBSTITUTE(IF(MID(I4,1,5)="Yes, ",MID(I4,6,100),I4)," ",",")) | AJ4: =IF(AC4="","",SUBSTITUTE(B4," ",",")) | AN4: =IF(AM4<>"",CONCATENATE(AC4," & ",SUBSTITUTE(AJ4,","," ")," & ",SUBSTITUTE(AF4,"."," ")," & ",AL4," & ",AM4," \\"),"")
A5: ACSALA | B5: C9 H8 O4 | C5: 0 | D5: Aspirin | E5: 2-Acetoxybenzoic acid | F5: Acetyl salicylic acid | G5: ACSALA21, ACSALA20, ACSALA23 | H5: Yes | I5: Yes, CSD version 5.41 | J5: \CHEMISTRY_CPOSS\0-EarlySearches\home\louise_price.eminerals\Aspirin | K5: Carole Ouvrard | L5: MOLPAK, DMAREL (3.0) | M5: Ouvrard, C., Price, S. L., Special Issue of Crystal Growth and Design, 4(6), 1119-1127 (2004) | N5: 2004 | O5: Yes | P5: In ACSALA_overview | Q5: Yes | T5: Yes | U5: Yes | W5: wc 15/12/2025 | X5: Aspirin_A1 | Y5: Yes | Z5: 3 | AA5: 13 | AB5: 5.59 | AC5: =IF(AND(A5<>A4,T5="Yes"),A5,"") -> ACSALA | AD5: Aspirin | AE5: =IF(AC5="","",MID(X5,1,(FIND("_",X5))-1)) -> Aspirin | AF5: =AE5 -> Aspirin | AG5: December2025 | AH5: A1 | AI5: =IF(AC5="","",SUBSTITUTE(IF(MID(I5,1,5)="Yes, ",MID(I5,6,100),I5)," ",",")) -> CSD,version,5.41 | AJ5: =IF(AC5="","",SUBSTITUTE(B5," ",",")) -> C9,H8,O4 | AL5: 1 | AM5: 1 | AN5: =IF(AM5<>"",CONCATENATE(AC5," & \ce{",SUBSTITUTE(AJ5,","," "),"} & ",SUBSTITUTE(AF5,"."," ")," & ",AL5," & ",AM5," \\"),"") -> ACSALA & \ce{C9 H8 O4} & Aspirin & 1 & 1 \\
A6: AFEBUI | B6: C7 H5 N1 O4 | C6: 0 | D6: Dipicolinic Acid | E6: Pyridine-2,6-dicarboxylic acid | G6: AFEBUI03 | H6: Yes | I6: Yes, CSD version 6.01 with Feb 2026 update | J6: \CHEMISTRY_CPOSS\DipicolinicAcid | K6: Not sure | L6: MOLPAK, DMACRYS (2.0.4) | M6: No publication planned | N6: pre-2010 | O6: Yes | P6: In AFEBUI_overview | Q6: Yes | T6: Yes | U6: Yes | W6: wc 01/06/2026 | X6: DipicolinicAcid_A1 | Y6: Yes | Z6: 1 | AA6: 365 | AB6: 25.32 | AC6: =IF(AND(A6<>A5,T6="Yes"),A6,"") -> AFEBUI | AD6: DipicolinicAcid | AE6: =IF(AC6="","",MID(X6,1,(FIND("_",X6))-1)) -> DipicolinicAcid | AF6: Dipicolinic.Acid | AG6: June2026 | AH6: A1 | AI6: =IF(AC6="","",SUBSTITUTE(IF(MID(I6,1,5)="Yes, ",MID(I6,6,100),I6)," ",",")) -> CSD,version,6.01,with,Feb,2026,update | AJ6: =IF(AC6="","",SUBSTITUTE(B6," ",",")) -> C7,H5,N1,O4 | AL6: 1 | AM6: 1 | AN6: =IF(AM6<>"",CONCATENATE(AC6," & \ce{",SUBSTITUTE(AJ6,","," "),"} & ",SUBSTITUTE(AF6,"."," ")," & ",AL6," & ",AM6," \\"),"") -> AFEBUI & \ce{C7 H5 N1 O4} & Dipicolinic Acid & 1 & 1 \\
A7: AFIGOO | B7: C2 H3 N1 O3 | C7: 0 | D7: Oxamic acid | E7: 2-amino-2-oxoacetic acid | G7: AFIGOO | H7: Yes | I7: Yes, CSD version 6.01 with Feb 2026 update | J7: \CHEMISTRY_CPOSS\0-EarlySearches\home\louise_price.eminerals\oxamic_acid | K7: Not sure | L7: MOLPAK, DMAREL (4.1.1) | M7: No publication planned | N7: pre-2010 | O7: Yes | P7: In AFIGOO_overview | Q7: Yes | T7: Yes | U7: Yes | W7: wc 01/06/2026 | X7: OxamicAcid_A1 | Y7: Yes | Z7: 1 | AA7: 350 | AB7: 19.52 | AC7: =IF(AND(A7<>A6,T7="Yes"),A7,"") -> AFIGOO | AD7: OxamicAcid | AE7: =IF(AC7="","",MID(X7,1,(FIND("_",X7))-1)) -> OxamicAcid | AF7: Oxamic.Acid | AG7: June2026 | AH7: A1 | AI7: =IF(AC7="","",SUBSTITUTE(IF(MID(I7,1,5)="Yes, ",MID(I7,6,100),I7)," ",",")) -> CSD,version,6.01,with,Feb,2026,update | AJ7: =IF(AC7="","",SUBSTITUTE(B7," ",",")) -> C2,H3,N1,O3 | AL7: 1 | AM7: 1 | AN7: =IF(AM7<>"",CONCATENATE(AC7," & \ce{",SUBSTITUTE(AJ7,","," "),"} & ",SUBSTITUTE(AF7,"."," ")," & ",AL7," & ",AM7," \\"),"") -> AFIGOO & \ce{C2 H3 N1 O3} & Oxamic Acid & 1 & 1 \\
A8: ALOXAN | B8: C4 H2 N2 O4 | C8: 0 | D8: Alloxan | E8: Pyrimidine-2,4,5,6-tetraone | G8: ALOXAN11, ALOXAN14 | H8: Yes | I8: Yes, CSD version 6.01 with Feb 2026 update | J8: \CHEMISTRY_CPOSS\0-EarlySearches\home\louise_price.eminerals\alloxan | K8: Tom Lewis | L8: MOLPAK, DMAREL (3.0) | M8: Lewis, T. C., Tocher, D. A., Price, S. L., Cryst. Growth Des., 5(3), 983-993 (2005) | N8: 2005 | O8: Yes | P8: In ALOXAN_overview | Q8: Yes | T8: Yes | U8: Yes | W8: wc 20/04/2026 | X8: Alloxan_A1 | Y8: Yes | Z8: 1 | AA8: 28 | AB8: 9.49 | AC8: =IF(AND(A8<>A7,T8="Yes"),A8,"") -> ALOXAN | AD8: Alloxan | AE8: =IF(AC8="","",MID(X8,1,(FIND("_",X8))-1)) -> Alloxan | AF8: =AE8 -> Alloxan | AG8: April2026 | AH8: A1 | AI8: =IF(AC8="","",SUBSTITUTE(IF(MID(I8,1,5)="Yes, ",MID(I8,6,100),I8)," ",",")) -> CSD,version,6.01,with,Feb,2026,update | AJ8: =IF(AC8="","",SUBSTITUTE(B8," ",",")) -> C4,H2,N2,O4 | AL8: 1 | AM8: 1 | AN8: =IF(AM8<>"",CONCATENATE(AC8," & \ce{",SUBSTITUTE(AJ8,","," "),"} & ",SUBSTITUTE(AF8,"."," ")," & ",AL8," & ",AM8," \\"),"") -> ALOXAN & \ce{C4 H2 N2 O4} & Alloxan & 1 & 1 \\
A9: AMBNAC | B9: C7 H7 N1 O2 | C9: 10 | D9: p-Aminobenzoic acid | E9: 4-Aminobenzoic acid | G9: AMBNAC19, AMBNAC12, AMBNAC16, AMBNAC09 | H9: Yes | I9: Yes, CSD version 6.01 with Feb 2026 update | J9: \CHEMISTRY_CPOSS\0-EarlySearches\home\louise_price.eminerals\aminobenzoic_acid_fit | K9: Nizar Issa / Panos Karamertzanis | L9: Study_ID=12, DMAREL (4.3.6) | M9: See Study_ID=12 | N9: 2009 | O9: Yes | P9: See Study_ID=12 | Q9: Yes | T9: Yes | U9: Yes | W9: wc 06/04/2026 | X9: AminobenzoicAcid_A3 | Y9: Yes | Z9: 1 | AA9: 59 | AB9: 26.512 | AC9: =IF(AND(A9<>A8,T9="Yes"),A9,"") -> AMBNAC | AD9: AminobenzoicAcid | AE9: =IF(AC9="","",MID(X9,1,(FIND("_",X9))-1)) -> AminobenzoicAcid | AF9: Aminobenzoic.Acid | AG9: April2026 | AH9: A2 | AI9: =IF(AC9="","",SUBSTITUTE(IF(MID(I9,1,5)="Yes, ",MID(I9,6,100),I9)," ",",")) -> CSD,version,6.01,with,Feb,2026,update | AJ9: =IF(AC9="","",SUBSTITUTE(B9," ",",")) -> C7,H7,N1,O2 | AL9: 1 | AM9: 3 | AN9: =IF(AM9<>"",CONCATENATE(AC9," & \ce{",SUBSTITUTE(AJ9,","," "),"} & ",SUBSTITUTE(AF9,"."," ")," & ",AL9," & ",AM9," \\"),"") -> AMBNAC & \ce{C7 H7 N1 O2} & Aminobenzoic Acid & 1 & 3 \\
A10: AMBNAC | B10: C7 H7 N1 O2 | C10: 11 | D10: p-Aminobenzoic acid | E10: 4-Aminobenzoic acid | G10: AMBNAC19, AMBNAC12, AMBNAC16, AMBNAC09 | H10: Yes | I10: Yes, CSD version 6.01 with Feb 2026 update | J10: \CHEMISTRY_CPOSS\0-EarlySearches\home\louise_price.eminerals\aminobenzoic_acid_will_singlepoint | K10: Nizar Issa / Panos Karamertzanis | L10: Flexible CrystalPredictor (1), DMAflex-Q, DMAflex (single iteration), DMACRYS (1.1.0) | M10: See Study_ID=12 | N10: 2009 | O10: Yes | P10: See Study_ID=12 | Q10: Yes | T10: Yes | U10: Yes | W10: wc 06/04/2026 | X10: AminobenzoicAcid_A1 | Y10: Yes | Z10: 1 | AA10: 605 | AB10: 37.685 | AC10: =IF(AND(A10<>A9,T10="Yes"),A10,"") | AE10: =IF(AC10="","",MID(X10,1,(FIND("_",X10))-1)) | AI10: =IF(AC10="","",SUBSTITUTE(IF(MID(I10,1,5)="Yes, ",MID(I10,6,100),I10)," ",",")) | AJ10: =IF(AC10="","",SUBSTITUTE(B10," ",",")) | AN10: =IF(AM10<>"",CONCATENATE(AC10," & ",SUBSTITUTE(AJ10,","," ")," & ",SUBSTITUTE(AF10,"."," ")," & ",AL10," & ",AM10," \\"),"")
A11: AMBNAC | B11: C7 H7 N1 O2 | C11: 12 | D11: p-Aminobenzoic acid | E11: 4-Aminobenzoic acid | G11: AMBNAC19, AMBNAC12, AMBNAC16, AMBNAC09 | H11: Yes | I11: Yes, CSD version 6.01 with Feb 2026 update | J11: \CHEMISTRY_CPOSS\0-EarlySearches\home\louise_price.eminerals\aminobenzoic_acid_will_full | K11: Nizar Issa / Panos Karamertzanis | L11: Study_ID=11, DMAflex, DMACRYS (1.1.0) | M11: Karamertzanis PG, Kazantsev AV, Issa N, Welch GWA, Adjiman CS, Pantelides CC, Price SL 2009. J Chem Theory Comput 5, 1432-1448. | N11: 2009 | O11: Yes | P11: In AMBNAC_overview | Q11: Yes | T11: Yes | U11: Yes | W11: wc 06/04/2026 | X11: AminobenzoicAcid_A2 | Y11: Yes | Z11: 1 | AA11: 25 | AB11: 10.72 | AC11: =IF(AND(A11<>A10,T11="Yes"),A11,"") | AE11: =IF(AC11="","",MID(X11,1,(FIND("_",X11))-1)) | AI11: =IF(AC11="","",SUBSTITUTE(IF(MID(I11,1,5)="Yes, ",MID(I11,6,100),I11)," ",",")) | AJ11: =IF(AC11="","",SUBSTITUTE(B11," ",",")) | AN11: =IF(AM11<>"",CONCATENATE(AC11," & ",SUBSTITUTE(AJ11,","," ")," & ",SUBSTITUTE(AF11,"."," ")," & ",AL11," & ",AM11," \\"),"")
A12: AMBZAM | B12: C7 H8 N2 O1 | C12: 0 | D12: 4-aminobenzamide | E12: 4-aminobenzamide | F12: 4-aminobenzamide | G12: AMBZAM11 | H12: Yes | I12: Yes, CSD version 6.01 | J12: \CHEMISTRY_CPOSS\0-EarlySearches\home\louise_price.eminerals\4-aminobenzamide | K12: Anastasia Ntantou | L12: MOLPAK, DMAREL (4.1.1) | M12: Masters Thesis only | N12: pre-2010 | O12: Yes | P12: In \CHEMISTRY_CPOSS\0-EarlySearches\home\louise_price.eminerals\2-aminobenzamide\JIXCIC_overview | Q12: Yes | T12: Yes | U12: Yes | W12: wc 12/01/2026 | X12: 4aminobenzamide_A1 | Y12: Yes | Z12: 1 | AA12: 244 | AB12: 15 | AC12: =IF(AND(A12<>A11,T12="Yes"),A12,"") -> AMBZAM | AD12: 1.SubstitutedBenzamides/4aminobenzamide | AE12: =IF(AC12="","",MID(X12,1,(FIND("_",X12))-1)) -> 4aminobenzamide | AF12: 4-aminobenzamide | AG12: January2026 | AH12: A1 | AI12: =IF(AC12="","",SUBSTITUTE(IF(MID(I12,1,5)="Yes, ",MID(I12,6,100),I12)," ",",")) -> CSD,version,6.01 | AJ12: =IF(AC12="","",SUBSTITUTE(B12," ",",")) -> C7,H8,N2,O1 | AL12: 1 | AM12: 1 | AN12: =IF(AM12<>"",CONCATENATE(AC12," & \ce{",SUBSTITUTE(AJ12,","," "),"} & ",SUBSTITUTE(AF12,"."," ")," & ",AL12," & ",AM12," \\"),"") -> AMBZAM & \ce{C7 H8 N2 O1} & 4-aminobenzamide & 1 & 1 \\
A13: AMOXAP | B13: C17 H16 N3 O1 Cl1 | C13: 0 | D13: Amoxapine | E13: 2-Chloro-11-(1-piperazinyl)-dibenz(b,f)(1,4)oxazepine | G13: AMOXAP | H13: Yes | I13: Yes, CSD version 5.46 with Feb 2025 update | J13: \CHEMISTRY_CPOSS\Olanzapine\Amoxapine\pbe_molpak | K13: Louise Price | L13: MOLPAK, DMACRYS (2.0.4) | M13: No publication planned | N13: 2012 | O13: Yes | Q13: Yes | T13: Yes | U13: Yes | W13: wc 01/12/2025 | X13: Amoxapine_A1 | Y13: Yes | Z13: 1 | AA13: 1512 | AB13: 30 | AC13: =IF(AND(A13<>A12,T13="Yes"),A13,"") -> AMOXAP | AD13: 1.OlanzapineFamily/Amoxapine | AE13: =IF(AC13="","",MID(X13,1,(FIND("_",X13))-1)) -> Amoxapine | AF13: =AE13 -> Amoxapine | AG13: December2025 | AH13: B2,A1 | AI13: =IF(AC13="","",SUBSTITUTE(IF(MID(I13,1,5)="Yes, ",MID(I13,6,100),I13)," ",",")) -> CSD,version,5.46,with,Feb,2025,update | AJ13: =IF(AC13="","",SUBSTITUTE(B13," ",",")) -> C17,H16,N3,O1,Cl1 | AK13: TricyclicCycloheptane | AL13: 2 | AM13: 3 | AN13: =IF(AM13<>"",CONCATENATE(AC13," & \ce{",SUBSTITUTE(AJ13,","," "),"} & ",SUBSTITUTE(AF13,"."," ")," & ",AL13," & ",AM13," \\"),"") -> AMOXAP & \ce{C17 H16 N3 O1 Cl1} & Amoxapine & 2 & 3 \\
A14: AMOXAP | B14: C17 H16 N3 O1 Cl1 | C14: 10 | D14: Amoxapine | E14: 2-Chloro-11-(1-piperazinyl)-dibenz(b,f)(1,4)oxazepine | G14: AMOXAP | H14: Yes | I14: Yes, CSD version 5.46 with Feb 2025 update | J14: \CHEMISTRY_CPOSS\Olanzapine\Amoxapine\Amox-CO | K14: Louise Price | L14: Study_id=20, CrystalOptimizer (2.3), DMACRYS (2.0.8) | M14: No publication planned | N14: 2015 | O14: Yes | Q14: Yes | T14: Yes | U14: Yes | W14: wc 01/12/2025 | X14: Amoxapine_B2 | Y14: Yes | Z14: 1 | AA14: 3634 | AB14: 30 | AC14: =IF(AND(A14<>A13,T14="Yes"),A14,"") | AE14: =IF(AC14="","",MID(X14,1,(FIND("_",X14))-1)) | AI14: =IF(AC14="","",SUBSTITUTE(IF(MID(I14,1,5)="Yes, ",MID(I14,6,100),I14)," ",",")) | AJ14: =IF(AC14="","",SUBSTITUTE(B14," ",",")) | AN14: =IF(AM14<>"",CONCATENATE(AC14," & ",SUBSTITUTE(AJ14,","," ")," & ",SUBSTITUTE(AF14,"."," ")," & ",AL14," & ",AM14," \\"),"")
A15: AMOXAP | B15: C17 H16 N3 O1 Cl1 | C15: 20 | D15: Amoxapine | E15: 2-Chloro-11-(1-piperazinyl)-dibenz(b,f)(1,4)oxazepine | G15: AMOXAP | H15: Yes | I15: Yes, CSD version 5.46 with Feb 2025 update | J15: \CHEMISTRY_CPOSS\Olanzapine\Amoxapine\Amox-CP | K15: Louise Price | L15: Flexible CrystalPredictor (2.1), DMACRYS (2.0.8) | M15: No publication planned | N15: 2015 | O15: Yes | Q15: Yes | T15: Yes | U15: Yes | W15: wc 01/12/2025 | X15: Amoxapine_B1 | Y15: Yes | Z15: 1 | AA15: 6801 | AB15: 30 | AC15: =IF(AND(A15<>A14,T15="Yes"),A15,"") | AE15: =IF(AC15="","",MID(X15,1,(FIND("_",X15))-1)) | AI15: =IF(AC15="","",SUBSTITUTE(IF(MID(I15,1,5)="Yes, ",MID(I15,6,100),I15)," ",",")) | AJ15: =IF(AC15="","",SUBSTITUTE(B15," ",",")) | AN15: =IF(AM15<>"",CONCATENATE(AC15," & ",SUBSTITUTE(AJ15,","," ")," & ",SUBSTITUTE(AF15,"."," ")," & ",AL15," & ",AM15," \\"),"")
A16: ANTCEN | B16: C14 H10 | C16: 0 | D16: Anthracene | E16: Anthracene | G16: ANTCEN; ANTCEN17; ANTCEN18 | H16: Yes | I16: Yes, CSD version 6.01 with Feb 2026 update | J16: \CHEMISTRY_CPOSS\0-EarlySearches\home\louise_price.eminerals\Anthracene | K16: Not sure | L16: MOLPAK, DMAREL (4.1.1) | M16: No publication planned | N16: pre-2010 | O16: Yes | P16: In ANTCEN_overview | Q16: Yes | T16: Yes | U16: Yes | W16: wc 01/06/2026 | X16: Anthracene_A1 | Y16: Yes | Z16: 1 | AA16: 67 | AB16: 5 | AC16: =IF(AND(A16<>A15,T16="Yes"),A16,"") -> ANTCEN | AD16: Anthracene | AE16: =IF(AC16="","",MID(X16,1,(FIND("_",X16))-1)) -> Anthracene | AF16: =AE16 -> Anthracene | AG16: June2026 | AH16: A1 | AI16: =IF(AC16="","",SUBSTITUTE(IF(MID(I16,1,5)="Yes, ",MID(I16,6,100),I16)," ",",")) -> CSD,version,6.01,with,Feb,2026,update | AJ16: =IF(AC16="","",SUBSTITUTE(B16," ",",")) -> C14,H10 | AL16: 1 | AM16: 1 | AN16: =IF(AM16<>"",CONCATENATE(AC16," & \ce{",SUBSTITUTE(AJ16,","," "),"} & ",SUBSTITUTE(AF16,"."," ")," & ",AL16," & ",AM16," \\"),"") -> ANTCEN & \ce{C14 H10} & Anthracene & 1 & 1 \\
A17: AVCZPA | B17: C15 H12 N2 O1 . C6 H6 N2 O1 | C17: 20 | D17: Carbamazepine picolinamide cocrystal | E17: 5-carbamoyl-5H-dibenz[b,f]azepine picolinamide | G17: Not on CSD | H17: Yes | I17: Yes, CSD version 6.01 with Feb 2026 update | J17: \CHEMISTRY_CPOSS\0-EarlySearches\home\louise_price.eminerals\carbamazepine-picolinamide | K17: Matthew Habgood | L17: Flexible CrystalPredictor (1), DMACRYS (1.1.1) | M17: Habgood M, Deij MA, Mazurek J, Price SL, ter Horst JH 2009. Cryst Growth Des 10, 903-912. | N17: 2009 | O17: Yes | P17: In AVCZPA_overview | Q17: Yes | T17: Yes | U17: Yes | W17: wc 04/05/2026 | X17: CarbamazepinePicolinamide_A1 | Y17: Yes | Z17: 0 | AA17: 43 | AB17: 18.11 | AC17: =IF(AND(A17<>A16,T17="Yes"),A17,"") -> AVCZPA | AD17: 1.Cocrystals/CarbamazepinePicolinamide | AE17: =IF(AC17="","",MID(X17,1,(FIND("_",X17))-1)) -> CarbamazepinePicolinamide | AF17: Carbamazepine.Picolinamide.cocrystal | AG17: May2026 | AH17: A1 | AI17: =IF(AC17="","",SUBSTITUTE(IF(MID(I17,1,5)="Yes, ",MID(I17,6,100),I17)," ",",")) -> CSD,version,6.01,with,Feb,2026,update | AJ17: =IF(AC17="","",SUBSTITUTE(B17," ",",")) -> C15,H12,N2,O1,.,C6,H6,N2,O1 | AK17: NotCrystallized | AL17: 1 | AM17: 1 | AN17: =IF(AM17<>"",CONCATENATE(AC17," & \ce{",SUBSTITUTE(AJ17,","," "),"} & ",SUBSTITUTE(AF17,"."," ")," & ",AL17," & ",AM17," \\"),"") -> AVCZPA & \ce{C15 H12 N2 O1 . C6 H6 N2 O1} & Carbamazepine Picolinamide cocrystal & 1 & 1 \\
A18: AXOSOW | B18: C3 H4 O1 | C18: 0 | D18: Propenal | E18: Propenal | F18: Blind Test XII | G18: AXOSOW | H18: Yes | I18: Yes, CSD version 6.01 | J18: \CHEMISTRY_CPOSS\0-EarlySearches\home\louise_price.eminerals\BlindTestXII\fit | K18: Unknown | L18: MOLPAK, DMAREL (4.1.1) | M18: Day GM, 2009. Acta Crystallogr , Sect B 65, 107-125. | N18: 2008 | O18: Yes | P18: In AXOSOW_overview | Q18: Yes | T18: Yes | U18: Yes | W18: wc 16/03/2026 | X18: BTXII_A1 | Y18: Yes | Z18: 1 | AA18: 413 | AB18: 10 | AC18: =IF(AND(A18<>A17,T18="Yes"),A18,"") -> AXOSOW | AD18: 1.BlindTest/XII | AE18: =IF(AC18="","",MID(X18,1,(FIND("_",X18))-1)) -> BTXII | AF18: Propenal.(Blind.Test.XII) | AG18: March2026 | AH18: A1 | AI18: =IF(AC18="","",SUBSTITUTE(IF(MID(I18,1,5)="Yes, ",MID(I18,6,100),I18)," ",",")) -> CSD,version,6.01 | AJ18: =IF(AC18="","",SUBSTITUTE(B18," ",",")) -> C3,H4,O1 | AK18: BlindTest | AL18: 1 | AM18: 2 | AN18: =IF(AM18<>"",CONCATENATE(AC18," & \ce{",SUBSTITUTE(AJ18,","," "),"} & ",SUBSTITUTE(AF18,"."," ")," & ",AL18," & ",AM18," \\"),"") -> AXOSOW & \ce{C3 H4 O1} & Propenal (Blind Test XII) & 1 & 2 \\
A19: AXOSOW | B19: C3 H4 O1 | C19: 1 | D19: Propenal | E19: Propenal | F19: Blind Test XII | G19: AXOSOW | H19: Yes | I19: Yes, CSD version 6.01 | J19: \CHEMISTRY_CPOSS\0-EarlySearches\home\louise_price.eminerals\BlindTestXII\williams | K19: Unknown | L19: MOLPAK, DMAREL (4.3.6) | M19: See Study_ID=0 | N19: 2008 | O19: Yes | P19: See Study_id=0 | Q19: Yes | T19: Yes | U19: Yes | W19: wc 16/03/2026 | X19: BTXII_A2 | Y19: Yes | Z19: 1 | AA19: 330 | AB19: 20 | AC19: =IF(AND(A19<>A18,T19="Yes"),A19,"") | AE19: =IF(AC19="","",MID(X19,1,(FIND("_",X19))-1)) | AI19: =IF(AC19="","",SUBSTITUTE(IF(MID(I19,1,5)="Yes, ",MID(I19,6,100),I19)," ",",")) | AJ19: =IF(AC19="","",SUBSTITUTE(B19," ",",")) | AN19: =IF(AM19<>"",CONCATENATE(AC19," & ",SUBSTITUTE(AJ19,","," ")," & ",SUBSTITUTE(AF19,"."," ")," & ",AL19," & ",AM19," \\"),"")
A20: AXUBUR | B20: C8 H5 F1 | C20: 0 | D20: 2-fluorophenylacetate | E20: 2-fluoroethynylbenzene | F20: 1-ethynyl-2-fluorobenzene | G20: AXUBUR, AXUBUR01, AXUBUR02 | H20: Yes | I20: Yes, CSD version 5.45 with Mar, Jun and Sep 2024 updates | J20: \CHEMISTRY_CPOSS\JoeRidout\2fluoroethynylbenzene | K20: Joe Ridout | L20: MOLPAK, DMACRYS (2.0.8b4) | M20: Ridout J, Price LS, Howard JAK, Probert MR 2014. Cryst Growth Des 14, 3384-3391. | N20: 2013 | O20: Yes | P20: In /CHEMISTRY_CPOSS/JoeRidout/ | Q20: Yes | T20: Yes | U20: Yes | W20: wc 27/01/2025 | X20: 2-fluoroethynylbenzene_A1 | Y20: Yes | Z20: 3 | AA20: 716 | AB20: 24.22 | AC20: =IF(AND(A20<>A19,T20="Yes"),A20,"") -> AXUBUR | AD20: Fluoroethynylbenzene | AE20: =IF(AC20="","",MID(X20,1,(FIND("_",X20))-1)) -> 2-fluoroethynylbenzene | AF20: 2-Fluoro.Ethynyl.Benzene | AG20: January2025 | AH20: A1 | AI20: =IF(AC20="","",SUBSTITUTE(IF(MID(I20,1,5)="Yes, ",MID(I20,6,100),I20)," ",",")) -> CSD,version,5.45,with,Mar,,Jun,and,Sep,2024,updates | AJ20: =IF(AC20="","",SUBSTITUTE(B20," ",",")) -> C8,H5,F1 | AL20: 1 | AM20: 2 | AN20: =IF(AM20<>"",CONCATENATE(AC20," & \ce{",SUBSTITUTE(AJ20,","," "),"} & ",SUBSTITUTE(AF20,"."," ")," & ",AL20," & ",AM20," \\"),"") -> AXUBUR & \ce{C8 H5 F1} & 2-Fluoro Ethynyl Benzene & 1 & 2 \\
A21: AXUBUR | B21: C8 H5 F1 | C21: 1 | D21: 2-fluorophenylacetate | E21: 2-fluoroethynylbenzene | F21: 1-ethynyl-2-fluorobenzene | G21: AXUBUR, AXUBUR01, AXUBUR02 | H21: Yes | I21: Yes, CSD version 5.45 with Mar, Jun and Sep 2024 updates | J21: \CHEMISTRY_CPOSS\JoeRidout\2fluoroethynylbenzene_0.55GPa | K21: Joe Ridout | L21: Study_ID=0, DMACRYS (2.0.8b4) with 0.55 GPa | M21: See Study_ID=0 | N21: 2013 | O21: Yes | P21: In /CHEMISTRY_CPOSS/JoeRidout/ | Q21: Yes | T21: Yes | U21: Yes | W21: wc 27/01/2025 | X21: 2-fluoroethynylbenzene_A2 | Y21: Yes | Z21: 3 | AA21: 514 | AB21: 24.88 | AC21: =IF(AND(A21<>A20,T21="Yes"),A21,"") | AE21: =IF(AC21="","",MID(X21,1,(FIND("_",X21))-1)) | AI21: =IF(AC21="","",SUBSTITUTE(IF(MID(I21,1,5)="Yes, ",MID(I21,6,100),I21)," ",",")) | AJ21: =IF(AC21="","",SUBSTITUTE(B21," ",",")) | AN21: =IF(AM21<>"",CONCATENATE(AC21," & ",SUBSTITUTE(AJ21,","," ")," & ",SUBSTITUTE(AF21,"."," ")," & ",AL21," & ",AM21," \\"),"")
A22: BARBAC | B22: C4 H4 N2 O3 | C22: 0 | D22: Barbituric Acid | E22: pyrimidine-2,4,6-trione | G22: BARBAC01, BARBAC02, BARBAC03 | H22: Yes | I22: Yes, CSD version 6.01 with Feb 2026 update | J22: \CHEMISTRY_CPOSS\0-EarlySearches\home\louise_price.eminerals\barbituric | K22: Tom Lewis | L22: MOLPAK, DMAREL (3.0) | M22: Lewis, T. C., Tocher, D. A., Price, S. L., Crystal Growth and Design, 4(5), 979-987 (2004) # Lewis, T. C., Tocher, D. A., Price, S. L., Cryst. Growth Des., 5(3), 983-993 (2005) | N22: 2005 | O22: Yes | P22: In BARBAC_overview | Q22: Yes | T22: Yes | U22: Yes | W22: wc 04/05/2026 | X22: BarbituricAcid_A1 | Y22: Yes | Z22: 2 | AA22: 84 | AB22: 8.43 | AC22: =IF(AND(A22<>A21,T22="Yes"),A22,"") -> BARBAC | AD22: BarbituricAcid | AE22: =IF(AC22="","",MID(X22,1,(FIND("_",X22))-1)) -> BarbituricAcid | AF22: Barbituric.Acid | AG22: May2026 | AH22: A1 | AI22: =IF(AC22="","",SUBSTITUTE(IF(MID(I22,1,5)="Yes, ",MID(I22,6,100),I22)," ",",")) -> CSD,version,6.01,with,Feb,2026,update | AJ22: =IF(AC22="","",SUBSTITUTE(B22," ",",")) -> C4,H4,N2,O3 | AL22: 1 | AM22: 1 | AN22: =IF(AM22<>"",CONCATENATE(AC22," & \ce{",SUBSTITUTE(AJ22,","," "),"} & ",SUBSTITUTE(AF22,"."," ")," & ",AL22," & ",AM22," \\"),"") -> BARBAC & \ce{C4 H4 N2 O3} & Barbituric Acid & 1 & 1 \\
A23: BAWNIW | B23: C8 N2 Cl4 | C23: 0 | D23: Chlorothalonil | E23: 2,4,5,6-tetrachloro-1,3-dicyanobenzene | F23: tetrachloroisophthalonitrile | G23: BAWNIW, BAWNIW06, BAWNIW02, BAWNIW07 | H23: Yes | I23: Yes, CSD version 5.46 with Feb 2025 update | J23: \CHEMISTRY_CPOSS\0-EarlySearches\home\louise_price.eminerals\chlorothalonil | K23: Helen Tsui | L23: MOLPAK, DMAREL (3.02) | M23: Tremayne M, Grice L, Pyatt JC, Seaton CC, Kariuki BM, Tsui HHY, Price SL, Cherryman JC, J Am Chem Soc, 126(22); 7071-7081 (2004) | N23: 2003 | O23: Yes | P23: Yes | Q23: Yes | T23: Yes | U23: Yes | W23: wc 17/03/2025 | X23: Chlorothalonil_A1 | Y23: Yes | Z23: 3 | AA23: 21 | AB23: 13.43 | AC23: =IF(AND(A23<>A22,T23="Yes"),A23,"") -> BAWNIW | AD23: Chlorothalonil | AE23: =IF(AC23="","",MID(X23,1,(FIND("_",X23))-1)) -> Chlorothalonil | AF23: =AE23 -> Chlorothalonil | AG23: March2025 | AH23: A1 | AI23: =IF(AC23="","",SUBSTITUTE(IF(MID(I23,1,5)="Yes, ",MID(I23,6,100),I23)," ",",")) -> CSD,version,5.46,with,Feb,2025,update | AJ23: =IF(AC23="","",SUBSTITUTE(B23," ",",")) -> C8,N2,Cl4 | AL23: 1 | AM23: 1 | AN23: =IF(AM23<>"",CONCATENATE(AC23," & \ce{",SUBSTITUTE(AJ23,","," "),"} & ",SUBSTITUTE(AF23,"."," ")," & ",AL23," & ",AM23," \\"),"") -> BAWNIW & \ce{C8 N2 Cl4} & Chlorothalonil & 1 & 1 \\
A24: BELBUP | B24: C5 H4 N4 O1 | C24: 0 | D24: Hydroxyazabenzotriazole | E24: 1-Hydroxy-7-Azabenzotriazole | F24: 3H-[1,2,3]triazolo[4,5-b]pyridin-3-ol | G24: BELBUP01, BELBUP02, BELBUP06 | H24: Yes | I24: Yes, CSD version 6.01 with Feb 2026 update | J24: \CHEMISTRY_CPOSS\0-EarlySearches\home\louise_price.eminerals\hydroxyazabenzotriazole | K24: Not sure | L24: MOLPAK, DMAREL (4.1.1) | M24: No publication planned | N24: pre-2010 | O24: Yes | P24: In BELBUP_overview | Q24: Yes | T24: Yes | U24: Yes | W24: wc 01/06/2026 | X24: Hydroxyazabenzotriazole_A1 | Y24: Yes | Z24: 2 | AA24: 48 | AB24: 5 | AC24: =IF(AND(A24<>A23,T24="Yes"),A24,"") -> BELBUP | AD24: Hydroxyazabenzotriazole | AE24: =IF(AC24="","",MID(X24,1,(FIND("_",X24))-1)) -> Hydroxyazabenzotriazole | AF24: =AE24 -> Hydroxyazabenzotriazole | AG24: June2026 | AH24: A1 | AI24: =IF(AC24="","",SUBSTITUTE(IF(MID(I24,1,5)="Yes, ",MID(I24,6,100),I24)," ",",")) -> CSD,version,6.01,with,Feb,2026,update | AJ24: =IF(AC24="","",SUBSTITUTE(B24," ",",")) -> C5,H4,N4,O1 | AL24: 1 | AM24: 1 | AN24: =IF(AM24<>"",CONCATENATE(AC24," & \ce{",SUBSTITUTE(AJ24,","," "),"} & ",SUBSTITUTE(AF24,"."," ")," & ",AL24," & ",AM24," \\"),"") -> BELBUP & \ce{C5 H4 N4 O1} & Hydroxyazabenzotriazole & 1 & 1 \\
A25: BESKAL | B25: C7 H6 O4 | C25: 20 | D25: Gentisic Acid | E25: 2,5-dihydroxybenzoic acid | F25: Gentisic Acid | G25: BESKAL14, BESKAL04 | H25: Yes | I25: Yes, CSD version 6.01 with Feb 2026 update | J25: \CHEMISTRY_CPOSS\0-EarlySearches\home\louise_price.eminerals\gentisic_acid | K25: Doris Braun | L25: Rigid Crystal Predictor (x), DMACRYS (2.0.2) | M25: Braun DE, Karamertzanis PG, Price SL 2011. Chem Commun 47, 5443-5445. | N25: 2010 | O25: Yes | P25: In BESKAL_overview | Q25: Yes | T25: Yes | U25: Yes | W25: wc 30/03/2026 | X25: GentisicAcid_A1 | Y25: Yes | Z25: 2 | AA25: 1064 | AB25: 20 | AC25: =IF(AND(A25<>A24,T25="Yes"),A25,"") -> BESKAL | AD25: GentisicAcid/GentisicAcid | AE25: =IF(AC25="","",MID(X25,1,(FIND("_",X25))-1)) -> GentisicAcid | AF25: Gentisic.Acid | AG25: March2026 | AH25: A1,B1 | AI25: =IF(AC25="","",SUBSTITUTE(IF(MID(I25,1,5)="Yes, ",MID(I25,6,100),I25)," ",",")) -> CSD,version,6.01,with,Feb,2026,update | AJ25: =IF(AC25="","",SUBSTITUTE(B25," ",",")) -> C7,H6,O4 | AL25: 2 | AM25: 2 | AN25: =IF(AM25<>"",CONCATENATE(AC25," & \ce{",SUBSTITUTE(AJ25,","," "),"} & ",SUBSTITUTE(AF25,"."," ")," & ",AL25," & ",AM25," \\"),"") -> BESKAL & \ce{C7 H6 O4} & Gentisic Acid & 2 & 2 \\
A26: BESKAL | B26: C7 H6 O4 | C26: 21 | D26: Gentisic Acid | E26: 2,5-dihydroxybenzoic acid | F26: Gentisic Acid | G26: BESKAL14, BESKAL04 | H26: Yes | I26: Yes, CSD version 6.01 with Feb 2026 update | J26: \CHEMISTRY_CPOSS\0-EarlySearches\home\louise_price.eminerals\gentisic_acidZ2 | K26: Doris Braun | L26: Rigid Crystal Predictor (x), DMACRYS (2.0.2) | M26: Braun DE, Karamertzanis PG, Price SL 2011. Chem Commun 47, 5443-5445. | N26: 2010 | O26: Yes | P26: See Study_ID=20 | Q26: Yes | T26: Yes | U26: Yes | W26: wc 30/03/2026 | X26: GentisicAcid_B1 | Y26: Yes | Z26: 2 | AA26: 6233 | AB26: 33.84 | AC26: =IF(AND(A26<>A25,T26="Yes"),A26,"") | AE26: =IF(AC26="","",MID(X26,1,(FIND("_",X26))-1)) | AI26: =IF(AC26="","",SUBSTITUTE(IF(MID(I26,1,5)="Yes, ",MID(I26,6,100),I26)," ",",")) | AJ26: =IF(AC26="","",SUBSTITUTE(B26," ",",")) | AN26: =IF(AM26<>"",CONCATENATE(AC26," & ",SUBSTITUTE(AJ26,","," ")," & ",SUBSTITUTE(AF26,"."," ")," & ",AL26," & ",AM26," \\"),"")
A27: BICVIS | B27: C6 H8 O4 | C27: 10 | D27: DD,LL-lactide | E27: rac-3,6-dimethyl-1,4-dioxane-2,5-dione | G27: BICVIS, NAHNOZ01, TOFTIV, BEYDEO01 | H27: Yes | I27: Yes, CSD version 5.46 with Feb 2025 update | J27: \CHEMISTRY_CPOSS\Lactides\CrystalOptimizer | K27: Rebecca Hylton | L27: Study_ID=20, CrystalOptimizer (2.3), DMACRYS (2.0.8) | M27: Buchholz HK, Hylton RK, Brandenburg JG, Seidel-Morgenstern A, Lorenz H, Stein M, Price SL, Cryst Growth Des 2017, 17 (9), 4676-4686 | N27: 2014 | O27: Yes | P27: In BICVIS_overview | Q27: Yes | T27: Yes | U27: Yes | W27: wc 31/03/2025 | X27: Lactide_A2 | Y27: Yes | Z27: 2 | AA27: 1201 | AB27: 24.072 | AC27: =IF(AND(A27<>A26,T27="Yes"),A27,"") -> BICVIS | AD27: Lactide | AE27: =IF(AC27="","",MID(X27,1,(FIND("_",X27))-1)) -> Lactide | AF27: =AE27 -> Lactide | AG27: March2025 | AH27: A2 | AI27: =IF(AC27="","",SUBSTITUTE(IF(MID(I27,1,5)="Yes, ",MID(I27,6,100),I27)," ",",")) -> CSD,version,5.46,with,Feb,2025,update | AJ27: =IF(AC27="","",SUBSTITUTE(B27," ",",")) -> C6,H8,O4 | AL27: 1 | AM27: 4 | AN27: =IF(AM27<>"",CONCATENATE(AC27," & \ce{",SUBSTITUTE(AJ27,","," "),"} & ",SUBSTITUTE(AF27,"."," ")," & ",AL27," & ",AM27," \\"),"") -> BICVIS & \ce{C6 H8 O4} & Lactide & 1 & 4 \\
A28: BICVIS | B28: C6 H8 O4 | C28: 20 | D28: DD,LL-lactide | E28: rac-3,6-dimethyl-1,4-dioxane-2,5-dione | G28: BICVIS, NAHNOZ01, TOFTIV, BEYDEO01 | H28: Yes | I28: Yes, CSD version 5.46 with Feb 2025 update | J28: \CHEMISTRY_CPOSS\Lactides\racemic-CrystalPredictor | K28: Rebecca Hylton | L28: Rigid Crystal Predictor (x), DMACRYS (2.0.8) | M28: See Study_ID=10 | N28: 2014 | O28: Yes | P28: See Study_ID=10 | Q28: Yes | T28: Yes | U28: Yes | W28: wc 31/03/2025 | X28: Lactide_A1 | Y28: Yes | Z28: 2 | AA28: 2170 | AB28: 20 | AC28: =IF(AND(A28<>A27,T28="Yes"),A28,"") | AE28: =IF(AC28="","",MID(X28,1,(FIND("_",X28))-1)) | AI28: =IF(AC28="","",SUBSTITUTE(IF(MID(I28,1,5)="Yes, ",MID(I28,6,100),I28)," ",",")) | AJ28: =IF(AC28="","",SUBSTITUTE(B28," ",",")) | AN28: =IF(AM28<>"",CONCATENATE(AC28," & ",SUBSTITUTE(AJ28,","," ")," & ",SUBSTITUTE(AF28,"."," ")," & ",AL28," & ",AM28," \\"),"")
A29: BICVIS | B29: C6 H8 O4 | C29: 30 | D29: DD,LL-lactide | E29: rac-3,6-dimethyl-1,4-dioxane-2,5-dione | G29: BICVIS, NAHNOZ01, TOFTIV, BEYDEO01 | H29: Yes | I29: Yes, CSD version 5.46 with Feb 2025 update | J29: \CHEMISTRY_CPOSS\Lactides\PCM_cuto15 | K29: Rebecca Hylton | L29: Study_ID=10, DMACRYS (2.0.8) | M29: See Study_ID=10 | N29: 2014 | O29: Yes | P29: See Study_ID=10 | Q29: Yes | T29: Yes | U29: Yes | W29: wc 31/03/2025 | X29: Lactide_A3 | Y29: Yes | Z29: 2 | AA29: 1239 | AB29: 26.807 | AC29: =IF(AND(A29<>A28,T29="Yes"),A29,"") | AE29: =IF(AC29="","",MID(X29,1,(FIND("_",X29))-1)) | AI29: =IF(AC29="","",SUBSTITUTE(IF(MID(I29,1,5)="Yes, ",MID(I29,6,100),I29)," ",",")) | AJ29: =IF(AC29="","",SUBSTITUTE(B29," ",",")) | AN29: =IF(AM29<>"",CONCATENATE(AC29," & ",SUBSTITUTE(AJ29,","," ")," & ",SUBSTITUTE(AF29,"."," ")," & ",AL29," & ",AM29," \\"),"")
A30: BICVIS | B30: C6 H8 O4 | C30: 31 | D30: DD,LL-lactide | E30: rac-3,6-dimethyl-1,4-dioxane-2,5-dione | G30: BICVIS, NAHNOZ01, TOFTIV, BEYDEO01 | H30: Yes | I30: Yes, CSD version 5.46 with Feb 2025 update | J30: \CHEMISTRY_CPOSS\Lactides\PCM_cuto30 | K30: Rebecca Hylton | L30: Study_ID=10, DMACRYS (2.0.8) | M30: See Study_ID=10 | N30: 2014 | O30: Yes | P30: See Study_ID=10 | Q30: Yes | T30: Yes | U30: Yes | W30: wc 31/03/2025 | X30: Lactide_A4 | Y30: Yes | Z30: 2 | AA30: 1239 | AB30: 26.807 | AC30: =IF(AND(A30<>A29,T30="Yes"),A30,"") | AE30: =IF(AC30="","",MID(X30,1,(FIND("_",X30))-1)) | AI30: =IF(AC30="","",SUBSTITUTE(IF(MID(I30,1,5)="Yes, ",MID(I30,6,100),I30)," ",",")) | AJ30: =IF(AC30="","",SUBSTITUTE(B30," ",",")) | AN30: =IF(AM30<>"",CONCATENATE(AC30," & ",SUBSTITUTE(AJ30,","," ")," & ",SUBSTITUTE(AF30,"."," ")," & ",AL30," & ",AM30," \\"),"")
A31: BIFHOP | B31: C20 H14 N1 O3 Cl2 F1 | C31: 0 | D31: GSK Compund C | E31: 6-[(5-Chloro-2-([(4-chloro-2-fluorophenyl)methyl]oxy)phenyl)methyl]-2-pyridinecarboxylic acid | G31: BIFHOP | H31: Yes | I31: Yes, CSD version 5.46 with Feb 2025 update | J31: \CHEMISTRY_CPOSS\GSK269984B\BIFHOP | K31: Salima Ismail / Louise Price | L31: MOLPAK, DMACRYS (2.0.4) | M31: See Study_ID=30 | N31: 2013 | O31: Yes | P31: See Study_ID=30 | Q31: Yes | T31: Yes | U31: Yes | W31: wc 17/03/2025 | X31: GSK269984B_A1 | Y31: Yes | Z31: 1 | AA31: 5662 | AB31: 68.66 | AC31: =IF(AND(A31<>A30,T31="Yes"),A31,"") -> BIFHOP | AD31: GSK269984B | AE31: =IF(AC31="","",MID(X31,1,(FIND("_",X31))-1)) -> GSK269984B | AF31: =AE31 -> GSK269984B | AG31: March2025 | AH31: C2 | AI31: =IF(AC31="","",SUBSTITUTE(IF(MID(I31,1,5)="Yes, ",MID(I31,6,100),I31)," ",",")) -> CSD,version,5.46,with,Feb,2025,update | AJ31: =IF(AC31="","",SUBSTITUTE(B31," ",",")) -> C20,H14,N1,O3,Cl2,F1 | AL31: 4 | AM31: 5 | AN31: =IF(AM31<>"",CONCATENATE(AC31," & \ce{",SUBSTITUTE(AJ31,","," "),"} & ",SUBSTITUTE(AF31,"."," ")," & ",AL31," & ",AM31," \\"),"") -> BIFHOP & \ce{C20 H14 N1 O3 Cl2 F1} & GSK269984B & 4 & 5 \\
A32: BIFHOP | B32: C20 H14 N1 O3 Cl2 F1 | C32: 1 | D32: GSK Compund C | E32: 6-[(5-Chloro-2-([(4-chloro-2-fluorophenyl)methyl]oxy)phenyl)methyl]-2-pyridinecarboxylic acid | G32: BIFHOP | H32: Yes | I32: Yes, CSD version 5.46 with Feb 2025 update | J32: \CHEMISTRY_CPOSS\GSK269984B\BIFHOP_Exp | K32: Salima Ismail / Louise Price | L32: MOLPAK, DMACRYS (2.0.4) | M32: See Study_ID=30 | N32: 2013 | O32: Yes | P32: See Study_ID=30 | Q32: Yes | T32: Yes | U32: Yes | W32: wc 17/03/2025 | X32: GSK269984B_B1 | Y32: Yes | Z32: 1 | AA32: 11 | AB32: 14.83 | AC32: =IF(AND(A32<>A31,T32="Yes"),A32,"") | AE32: =IF(AC32="","",MID(X32,1,(FIND("_",X32))-1)) | AI32: =IF(AC32="","",SUBSTITUTE(IF(MID(I32,1,5)="Yes, ",MID(I32,6,100),I32)," ",",")) | AJ32: =IF(AC32="","",SUBSTITUTE(B32," ",",")) | AN32: =IF(AM32<>"",CONCATENATE(AC32," & ",SUBSTITUTE(AJ32,","," ")," & ",SUBSTITUTE(AF32,"."," ")," & ",AL32," & ",AM32," \\"),"")
A33: BIFHOP | B33: C20 H14 N1 O3 Cl2 F1 | C33: 10 | D33: GSK Compund C | E33: 6-[(5-Chloro-2-([(4-chloro-2-fluorophenyl)methyl]oxy)phenyl)methyl]-2-pyridinecarboxylic acid | G33: BIFHOP | H33: Yes | I33: Yes, CSD version 5.46 with Feb 2025 update | J33: \CHEMISTRY_CPOSS\GSK269984B\CrystalOptimizer | K33: Salima Ismail / Louise Price | L33: Flexible CrystalPredictor (1.x), CrystalOptimizer (x), DMACRYS (2.0.4) | M33: See Study_ID=30 | N33: 2013 | O33: Yes | P33: See Study_ID=30 | Q33: Yes | T33: Yes | U33: Yes | W33: wc 17/03/2025 | X33: GSK269984B_C1 | Y33: Yes | Z33: 1 | AA33: 528 | AB33: 90.274 | AC33: =IF(AND(A33<>A32,T33="Yes"),A33,"") | AE33: =IF(AC33="","",MID(X33,1,(FIND("_",X33))-1)) | AI33: =IF(AC33="","",SUBSTITUTE(IF(MID(I33,1,5)="Yes, ",MID(I33,6,100),I33)," ",",")) | AJ33: =IF(AC33="","",SUBSTITUTE(B33," ",",")) | AN33: =IF(AM33<>"",CONCATENATE(AC33," & ",SUBSTITUTE(AJ33,","," ")," & ",SUBSTITUTE(AF33,"."," ")," & ",AL33," & ",AM33," \\"),"")
A34: BIFHOP | B34: C20 H14 N1 O3 Cl2 F1 | C34: 30 | D34: GSK Compund C | E34: 6-[(5-Chloro-2-([(4-chloro-2-fluorophenyl)methyl]oxy)phenyl)methyl]-2-pyridinecarboxylic acid | G34: BIFHOP | H34: Yes | I34: Yes, CSD version 5.46 with Feb 2025 update | J34: \CHEMISTRY_CPOSS\GSK269984B\BIFHOP_PCM | K34: Salima Ismail / Louise Price | L34: Study_ID=10, DMACRYS (2.0.4) | M34: Ismail SZ, Anderton CL, Copley RCB, Price LS, Price SL 2013. Cryst Growth Des 13, 2396-2406. | N34: 2013 | O34: Yes | P34: In BIFHOP_overview | Q34: Yes | T34: Yes | U34: Yes | W34: wc 17/03/2025 | X34: GSK269984B_C2 | Y34: Yes | Z34: 1 | AA34: 520 | AB34: 76.482 | AC34: =IF(AND(A34<>A33,T34="Yes"),A34,"") | AE34: =IF(AC34="","",MID(X34,1,(FIND("_",X34))-1)) | AI34: =IF(AC34="","",SUBSTITUTE(IF(MID(I34,1,5)="Yes, ",MID(I34,6,100),I34)," ",",")) | AJ34: =IF(AC34="","",SUBSTITUTE(B34," ",",")) | AN34: =IF(AM34<>"",CONCATENATE(AC34," & ",SUBSTITUTE(AJ34,","," ")," & ",SUBSTITUTE(AF34,"."," ")," & ",AL34," & ",AM34," \\"),"")
A35: BIFHOP | B35: C20 H14 N1 O3 Cl2 F1 | C35: 60 | D35: GSK Compund C | E35: 6-[(5-Chloro-2-([(4-chloro-2-fluorophenyl)methyl]oxy)phenyl)methyl]-2-pyridinecarboxylic acid | G35: BIFHOP | H35: Yes | I35: Yes, CSD version 5.46 with Feb 2025 update | J35: \CHEMISTRY_CPOSS\LucasSearches\GSK_moleculeC | K35: Luca Iuzzolino | L35: Flexible CrystalPredictor (1.8), DFTB, DMACRYS (2.2.0.1) | M35: Iuzzolino L, McCabe P, Price SL, Brandenburg JG, Faraday Discussions 2018, 211, 275-296. | N35: 2018 | O35: Yes | P35: See Study_ID=30 | Q35: Yes | T35: Yes | U35: Yes | W35: wc 24/03/2025 | X35: GSK269984B_D1 | Y35: Yes | Z35: 1 | AA35: 485 | AB35: 20 | AC35: =IF(AND(A35<>A34,T35="Yes"),A35,"") | AE35: =IF(AC35="","",MID(X35,1,(FIND("_",X35))-1)) | AI35: =IF(AC35="","",SUBSTITUTE(IF(MID(I35,1,5)="Yes, ",MID(I35,6,100),I35)," ",",")) | AJ35: =IF(AC35="","",SUBSTITUTE(B35," ",",")) | AN35: =IF(AM35<>"",CONCATENATE(AC35," & ",SUBSTITUTE(AJ35,","," ")," & ",SUBSTITUTE(AF35,"."," ")," & ",AL35," & ",AM35," \\"),"")
A36: BIGSUF | B36: C7 H6 N1 O1 F1 | C36: 0 | D36: 2-fluorobenzamide | E36: 2-fluorobenzamide | F36: 2-fluorobenzamide | G36: BIGSUF01 | H36: Yes | I36: Yes, CSD version 6.01 | J36: \CHEMISTRY_CPOSS\0-EarlySearches\home\louise_price.eminerals\2-fluorobenzamide\opt | K36: Anastasia Ntantou | L36: MOLPAK, DMAREL (4.1.1) | M36: Masters Thesis only | N36: pre-2010 | O36: Yes | P36: In S, \CHEMISTRY_CPOSS\2-chlorobenzamide_CPCO\CLBZAM_overview | Q36: Yes | T36: Yes | U36: Yes | W36: wc 12/01/2026 | X36: 2fluorobenzamide_A1 | Y36: Yes | Z36: 1 | AA36: 418 | AC36: =IF(AND(A36<>A35,T36="Yes"),A36,"") -> BIGSUF | AD36: 1.SubstitutedBenzamides/2fluorobenzamide | AE36: =IF(AC36="","",MID(X36,1,(FIND("_",X36))-1)) -> 2fluorobenzamide | AF36: 2-fluorobenzamide | AG36: December2025 | AH36: A1,B1 | AI36: =IF(AC36="","",SUBSTITUTE(IF(MID(I36,1,5)="Yes, ",MID(I36,6,100),I36)," ",",")) -> CSD,version,6.01 | AJ36: =IF(AC36="","",SUBSTITUTE(B36," ",",")) -> C7,H6,N1,O1,F1 | AL36: 2 | AM36: 2 | AN36: =IF(AM36<>"",CONCATENATE(AC36," & \ce{",SUBSTITUTE(AJ36,","," "),"} & ",SUBSTITUTE(AF36,"."," ")," & ",AL36," & ",AM36," \\"),"") -> BIGSUF & \ce{C7 H6 N1 O1 F1} & 2-fluorobenzamide & 2 & 2 \\
A37: BIGSUF | B37: C7 H6 N1 O1 F1 | C37: 1 | D37: 2-fluorobenzamide | E37: 2-fluorobenzamide | F37: 2-fluorobenzamide | G37: BIGSUF01 | H37: Yes | I37: Yes, CSD version 6.01 | J37: \CHEMISTRY_CPOSS\0-EarlySearches\home\louise_price.eminerals\2-fluorobenzamide\con_opt | K37: Anastasia Ntantou | L37: MOLPAK, DMAREL (4.1.1) | M37: Masters Thesis only | N37: pre-2010 | O37: Yes | P37: In S, \CHEMISTRY_CPOSS\2-chlorobenzamide_CPCO\CLBZAM_overview | Q37: Yes | T37: Yes | U37: Yes | W37: wc 12/01/2026 | X37: 2fluorobenzamide_B1 | Y37: Yes | Z37: 1 | AA37: 159 | AC37: =IF(AND(A37<>A36,T37="Yes"),A37,"") | AE37: =IF(AC37="","",MID(X37,1,(FIND("_",X37))-1)) | AI37: =IF(AC37="","",SUBSTITUTE(IF(MID(I37,1,5)="Yes, ",MID(I37,6,100),I37)," ",",")) | AJ37: =IF(AC37="","",SUBSTITUTE(B37," ",",")) | AN37: =IF(AM37<>"",CONCATENATE(AC37," & ",SUBSTITUTE(AJ37,","," ")," & ",SUBSTITUTE(AF37,"."," ")," & ",AL37," & ",AM37," \\"),"")
A38: BIPYRL | B38: C10 H8 N2 | C38: 10 | D38: 2,2'-Bipyridyl | E38: 2,2'-Bipyridyl | F38: 2,2'-Bipyridyl | G38: BIPYRL04 | H38: Yes | I38: Yes, CSD version 6.01 with Feb 2026 update | J38: \CHEMISTRY_CPOSS\0-EarlySearches\home\louise_price.eminerals\bipyridine_fit | K38: Nizar Issa / Panos Karamertzanis | L38: Study_ID=11, DMAREL (4.3.6) | M38: See Study_ID=12 | N38: 2009 | O38: Yes | P38: See Study_ID=13 | Q38: Yes | T38: Yes | U38: Yes | W38: wc 06/04/2026 | X38: Bipyridine_A3 | Y38: Yes | Z38: 1 | AA38: 151 | AB38: 8.012 | AC38: =IF(AND(A38<>A37,T38="Yes"),A38,"") -> BIPYRL | AD38: Bipyridine | AE38: =IF(AC38="","",MID(X38,1,(FIND("_",X38))-1)) -> Bipyridine | AF38: =AE38 -> Bipyridine | AG38: April2026 | AH38: A2,B2 | AI38: =IF(AC38="","",SUBSTITUTE(IF(MID(I38,1,5)="Yes, ",MID(I38,6,100),I38)," ",",")) -> CSD,version,6.01,with,Feb,2026,update | AJ38: =IF(AC38="","",SUBSTITUTE(B38," ",",")) -> C10,H8,N2 | AL38: 2 | AM38: 5 | AN38: =IF(AM38<>"",CONCATENATE(AC38," & \ce{",SUBSTITUTE(AJ38,","," "),"} & ",SUBSTITUTE(AF38,"."," ")," & ",AL38," & ",AM38," \\"),"") -> BIPYRL & \ce{C10 H8 N2} & Bipyridine & 2 & 5 \\
A39: BIPYRL | B39: C10 H8 N2 | C39: 11 | D39: 2,2'-Bipyridyl | E39: 2,2'-Bipyridyl | F39: 2,2'-Bipyridyl | G39: BIPYRL04 | H39: Yes | I39: Yes, CSD version 6.01 with Feb 2026 update | J39: \CHEMISTRY_CPOSS\0-EarlySearches\home\louise_price.eminerals\bipyridyl_will_singlepoint | K39: Nizar Issa / Panos Karamertzanis | L39: Flexible CrystalPredictor (1), DMAflex-Q, DMAflex (single iteration), DMACRYS (1.0.1) | M39: See Study_ID=12 | N39: 2009 | O39: Yes | P39: See Study_ID=13 | Q39: Yes | T39: Yes | U39: Yes | W39: wc 06/04/2026 | X39: Bipyridine_A1 | Y39: Yes | Z39: 1 | AA39: 495 | AB39: 12.524 | AC39: =IF(AND(A39<>A38,T39="Yes"),A39,"") | AE39: =IF(AC39="","",MID(X39,1,(FIND("_",X39))-1)) | AI39: =IF(AC39="","",SUBSTITUTE(IF(MID(I39,1,5)="Yes, ",MID(I39,6,100),I39)," ",",")) | AJ39: =IF(AC39="","",SUBSTITUTE(B39," ",",")) | AN39: =IF(AM39<>"",CONCATENATE(AC39," & ",SUBSTITUTE(AJ39,","," ")," & ",SUBSTITUTE(AF39,"."," ")," & ",AL39," & ",AM39," \\"),"")
A40: BIPYRL | B40: C10 H8 N2 | C40: 12 | D40: 2,2'-Bipyridyl | E40: 2,2'-Bipyridyl | F40: 2,2'-Bipyridyl | G40: BIPYRL04 | H40: Yes | I40: Yes, CSD version 6.01 with Feb 2026 update | J40: \CHEMISTRY_CPOSS\0-EarlySearches\home\louise_price.eminerals\bipyridyl_will_full | K40: Nizar Issa / Panos Karamertzanis | L40: Study_ID=11, DMAflex, DMACRYS (1.0.1 and 1.1.0) | M40: Karamertzanis PG, Kazantsev AV, Issa N, Welch GWA, Adjiman CS, Pantelides CC, Price SL 2009. J Chem Theory Comput 5, 1432-1448. | N40: 2009 | O40: Yes | P40: See Study_ID=13 | Q40: Yes | T40: Yes | U40: Yes | W40: wc 06/04/2026 | X40: Bipyridine_A2 | Y40: Yes | Z40: 1 | AA40: 20 | AB40: 3.216 | AC40: =IF(AND(A40<>A39,T40="Yes"),A40,"") | AE40: =IF(AC40="","",MID(X40,1,(FIND("_",X40))-1)) | AI40: =IF(AC40="","",SUBSTITUTE(IF(MID(I40,1,5)="Yes, ",MID(I40,6,100),I40)," ",",")) | AJ40: =IF(AC40="","",SUBSTITUTE(B40," ",",")) | AN40: =IF(AM40<>"",CONCATENATE(AC40," & ",SUBSTITUTE(AJ40,","," ")," & ",SUBSTITUTE(AF40,"."," ")," & ",AL40," & ",AM40," \\"),"")
...

Sheet Sheet1
A1: Scientist | B1: Date | G1: 23-dichloronitrobenzene
A2: Helen Tsui | B2: 2003 | G2: 24-dichloronitrobenzene
A3: Antonio Torrisi | B3: 2004 | G3: 25-dichloronitrobenzene
A4: Binal Patel / Tom Lewis | B4: 2004 | G4: 26-dichloronitrobenzene
A5: Carole Ouvrard | B5: 2004 | G5: 2-Aminobenzamide
A6: Pinky Pridhanani-Jethani / Tom Lewis | B6: 2004 | G6: 2-AminobenzoicAcid
A7: Sarah Barnett | B7: 2004 | G7: 2bromobenzamide
A8: Tom Lewis | B8: 2004 | G8: 2C4NBA
A9: Antonio Torrisi | B9: 2005 | G9: 2C5NBA
A10: Ashley Hulme | B10: 2005 | G10: 2chlorobenzamide
A11: Harriott Nowell | B11: 2005 | G11: 2fluorobenzamide
A12: Juliette Pradon / Sarah Barnett | B12: 2005 | G12: 2-fluoroethynylbenzene
A13: Panos Karamertzanis | B13: 2005 | G13: 2-fluorotoluene
... A15: Tom Lewis | B15: 2005 | G15: 2M4NBA
A16: Ashley Hulme | B16: 2005-7 | G16: 34-dichloronitrobenzene
A17: Ashley Hulme / Sarah Barnett | B17: 2005-7 | G17: 34-dinitrochlorobenzene
A18: Nizar Issa | B18: 2005-7 | G18: 35-dichloronitrobenzene
A19: Nizar Issa / Sarah Barnett | B19: 2005-7 | G19: 3aminobenzamide
A20: Sarah Barnett | B20: 2005-7 | G20: 3-fluorotoluene
A21: Tom Lewis | B21: 2005-7 | G21: 3-HydroxybenzoicAcid
A22: Sarah Barnett | B22: 2005-8 | G22: 3Oxauracil
A23: Ashley Hulme | B23: 2006 | G23: 4-Aminobenzamide
A24: Ashley Hulme | B24: 2007 | G24: 4-AminobenzoicAcid
A25: Antonio Torrisi | B25: 2008 | G25: 4C2NBA
A26: Gareth Welch | B26: 2008 | G26: 4-CyanoPyridine
A27: Gareth Welch / Alston Misquitta | B27: 2008 | G27: 4Dimethylaminopyridine
A28: Nizar Issa (Louise Price) | B28: 2008 | G28: 4-FluorobenzoicAcid
A29: Panos Karamertzanis | B29: 2008 | G29: 4-fluorotoluene
A30: Sally Price | B30: 2008 | G30: 4-HydroxybenzoicAcid
A31: Sharmarke Mohamed | B31: 2008 | G31: 4Hydroxycoumarin
A32: Emiliana D'Oria | B32: 2009 | G32: 5aminouracil
A33: Matthew Habgood | B33: 2009 | G33: 5Azauracil
A34: Nizar Issa / Panos Karamertzanis | B34: 2009 | G34: 5C2NBA
A35: Panos Karamertzanis | B35: 2009 | G35: 5chlorouracil
A36: Emiliana D'Oria / Doris Braun | B36: 2009-2010 | G36: 5cyanouracil
A37: Alston Misquitta | B37: 2010 | G37: 5eniluracil
A38: Andrei Kazantsev | B38: 2010 | G38: 5ethyluracil
A39: Doris Braun | B39: 2010 | G39: 5fluorocytosine
A40: Louise Price | B40: 2010 | G40: 5fluoroisatin
A41: Louise Price / Einat Schur | B41: 2010 | G41: 5nitrouracil
...

Sheet Progress
A1: Week | B1: Date | C1: Number this week | D1: Running total | E1: Running percentage | F1: Target number | G1: On target? | H1: =COUNTA(Database!X$2:X$549) -> 524 | I1: =H1/533 -> 0.98311445
A2: 1 | B2: 28/10/2024 | C2: =COUNTIF(Database!W:W,CONCATENATE("wc ",B2)) -> 12 | D2: =C2 -> 12 | E2: =D2/533*100 -> 2.2514071 | F2: =ROUNDUP(533/53*A2,0) -> 11 | G2: =IF(D2>=F2,"Yay!","Oh No!") -> Yay!
A3: 2 | B3: 04/11/2024 | C3: =COUNTIF(Database!W:W,CONCATENATE("wc ",B3)) -> 11 | D3: =D2+C3 -> 23 | E3: =D3/533*100 -> 4.315197 | F3: =ROUNDUP(533/53*A3,0) -> 21 | G3: =IF(D3>=F3,"Yay!","Oh No!") -> Yay!
A4: 3 | B4: 11/11/2024 | C4: =COUNTIF(Database!W:W,CONCATENATE("wc ",B4)) -> 28 | D4: =D3+C4 -> 51 | E4: =D4/533*100 -> 9.5684803 | F4: =ROUNDUP(533/53*A4,0) -> 31 | G4: =IF(D4>=F4,"Yay!","Oh No!") -> Yay!
A5: 4 | B5: 18/11/2024 | C5: =COUNTIF(Database!W:W,CONCATENATE("wc ",B5)) -> 5 | D5: =D4+C5 -> 56 | E5: =D5/533*100 -> 10.506567 | F5: =ROUNDUP(533/53*A5,0) -> 41 | G5: =IF(D5>=F5,"Yay!","Oh No!") -> Yay!
A6: 5 | B6: 25/11/2024 | C6: =COUNTIF(Database!W:W,CONCATENATE("wc ",B6)) -> 13 | D6: =D5+C6 -> 69 | E6: =D6/533*100 -> 12.945591 | F6: =ROUNDUP(533/53*A6,0) -> 51 | G6: =IF(D6>=F6,"Yay!","Oh No!") -> Yay!
A7: 6 | B7: 02/12/2024 | C7: =COUNTIF(Database!W:W,CONCATENATE("wc ",B7)) -> 5 | D7: =D6+C7 -> 74 | E7: =D7/533*100 -> 13.883677 | F7: =ROUNDUP(533/53*A7,0) -> 61 | G7: =IF(D7>=F7,"Yay!","Oh No!") -> Yay!
A8: 7 | B8: 09/12/2024 | C8: =COUNTIF(Database!W:W,CONCATENATE("wc ",B8)) -> 17 | D8: =D7+C8 -> 91 | E8: =D8/533*100 -> 17.073171 | F8: =ROUNDUP(533/53*A8,0) -> 71 | G8: =IF(D8>=F8,"Yay!","Oh No!") -> Yay!
A9: 8 | B9: 16/12/2024 | C9: =COUNTIF(Database!W:W,CONCATENATE("wc ",B9)) -> 0 | D9: =D8+C9 -> 91 | E9: =D9/533*100 -> 17.073171 | F9: =ROUNDUP(533/53*A9,0) -> 81 | G9: =IF(D9>=F9,"Yay!","Oh No!") -> Yay!
A10: 9 | B10: 06/01/2025 | C10: =COUNTIF(Database!W:W,CONCATENATE("wc ",B10)) -> 0 | D10: =D9+C10 -> 91 | E10: =D10/533*100 -> 17.073171 | F10: =ROUNDUP(533/53*A10,0) -> 91 | G10: =IF(D10>=F10,"Yay!","Oh No!") -> Yay!
A11: 10 | B11: 13/01/2025 | C11: =COUNTIF(Database!W:W,CONCATENATE("wc ",B11)) -> 9 | D11: =D10+C11 -> 100 | E11: =D11/533*100 -> 18.761726 | F11: =ROUNDUP(533/53*A11,0) -> 101 | G11: =IF(D11>=F11,"Yay!","Oh No!") -> Oh No!
A12: 11 | B12: 20/01/2025 | C12: =COUNTIF(Database!W:W,CONCATENATE("wc ",B12)) -> 3 | D12: =D11+C12 -> 103 | E12: =D12/533*100 -> 19.324578 | F12: =ROUNDUP(533/53*A12,0) -> 111 | G12: =IF(D12>=F12,"Yay!","Oh No!") -> Oh No!
A13: 12 | B13: 27/01/2025 | C13: =COUNTIF(Database!W:W,CONCATENATE("wc ",B13)) -> 3 | D13: =D12+C13 -> 106 | E13: =D13/533*100 -> 19.88743 | F13: =ROUNDUP(533/53*A13,0) -> 121 | G13: =IF(D13>=F13,"Yay!","Oh No!") -> Oh No!
A14: 13 | B14: 03/02/2025 | C14: =COUNTIF(Database!W:W,CONCATENATE("wc ",B14)) -> 0 | D14: =D13+C14 -> 106 | E14: =D14/533*100 -> 19.88743 | F14: =ROUNDUP(533/53*A14,0) -> 131 | G14: =IF(D14>=F14,"Yay!","Oh No!") -> Oh No!
... A53: 52 | B53: 24/11/2025 | C53: =COUNTIF(Database!W:W,CONCATENATE("wc ",B53)) -> 8 | D53: =D52+C53 -> 146 | E53: =D53/533*100 -> 27.39212 | F53: =ROUNDUP(533/53*A53,0) -> 523 | G53: =IF(D53>=F53,"Yay!","Oh No!") -> Oh No!
A54: 53 | B54: 01/12/2025 | C54: =COUNTIF(Database!W:W,CONCATENATE("wc ",B54)) -> 6 | D54: =D53+C54 -> 152 | E54: =D54/533*100 -> 28.517824 | F54: 539 | G54: =IF(D54>=F54,"Yay!","Oh No!") -> Oh No!
A55: 54 | B55: 08/12/2025 | C55: =COUNTIF(Database!W:W,CONCATENATE("wc ",B55)) -> 15 | D55: =D54+C55 -> 167 | E55: =D55/533*100 -> 31.332083 | F55: 539 | G55: =IF(D55>=F55,"Yay!","Oh No!") -> Oh No!
A56: 55 | B56: 15/12/2025 | C56: =COUNTIF(Database!W:W,CONCATENATE("wc ",B56)) -> 15 | D56: =D55+C56 -> 182 | E56: =D56/533*100 -> 34.146341 | F56: 541 | G56: =IF(D56>=F56,"Yay!","Oh No!") -> Oh No!
A57: 56 | B57: 05/01/2026 | C57: =COUNTIF(Database!W:W,CONCATENATE("wc ",B57)) -> 0 | D57: =D56+C57 -> 182 | E57: =D57/533*100 -> 34.146341 | F57: 539 | G57: =IF(D57>=F57,"Yay!","Oh No!") -> Oh No!
A58: 57 | B58: 12/01/2026 | C58: =COUNTIF(Database!W:W,CONCATENATE("wc ",B58)) -> 30 | D58: =D57+C58 -> 212 | E58: =D58/533*100 -> 39.774859 | F58: 539 | G58: =IF(D58>=F58,"Yay!","Oh No!") -> Oh No!
A59: 58 | B59: 19/01/2026 | C59: =COUNTIF(Database!W:W,CONCATENATE("wc ",B59)) -> 17 | D59: =D58+C59 -> 229 | E59: =D59/533*100 -> 42.964353 | F59: 544 | G59: =IF(D59>=F59,"Yay!","Oh No!") -> Oh No!
A60: 59 | B60: 26/01/2026 | C60: =COUNTIF(Database!W:W,CONCATENATE("wc ",B60)) -> 14 | D60: =D59+C60 -> 243 | E60: =D60/533*100 -> 45.590994 | F60: 544 | G60: =IF(D60>=F60,"Yay!","Oh No!") -> Oh No!
A61: 60 | B61: 02/02/2026 | C61: =COUNTIF(Database!W:W,CONCATENATE("wc ",B61)) -> 0 | D61: =D60+C61 -> 243 | E61: =D61/533*100 -> 45.590994 | F61: 544 | G61: =IF(D61>=F61,"Yay!","Oh No!") -> Oh No!
A62: 61 | B62: 09/02/2026 | C62: =COUNTIF(Database!W:W,CONCATENATE("wc ",B62)) -> 0 | D62: =D61+C62 -> 243 | E62: =D62/533*100 -> 45.590994 | F62: 544 | G62: =IF(D62>=F62,"Yay!","Oh No!") -> Oh No!
A63: 62 | B63: 16/02/2026 | C63: =COUNTIF(Database!W:W,CONCATENATE("wc ",B63)) -> 0 | D63: =D62+C63 -> 243 | E63: =D63/533*100 -> 45.590994 | F63: 544 | G63: =IF(D63>=F63,"Yay!","Oh No!") -> Oh No!
A64: 63 | B64: 23/02/2026 | C64: =COUNTIF(Database!W:W,CONCATENATE("wc ",B64)) -> 1 | D64: =D63+C64 -> 244 | E64: =D64/533*100 -> 45.778612 | F64: 544 | G64: =IF(D64>=F64,"Yay!","Oh No!") -> Oh No!
A65: 64 | B65: 02/03/2026 | C65: =COUNTIF(Database!W:W,CONCATENATE("wc ",B65)) -> 48 | D65: =D64+C65 -> 292 | E65: =D65/533*100 -> 54.78424 | F65: 544 | G65: =IF(D65>=F65,"Yay!","Oh No!") -> Oh No!
... A79: 78 | B79: 08/06/2026 | C79: =COUNTIF(Database!W:W,CONCATENATE("wc ",B79)) -> 11 | D79: =D78+C79 -> 541 | E79: =D79/533*100 -> 101.50094 | F79: 548 | G79: =IF(D79>=F79,"Yay!","Oh No!") -> Oh No!
A80: 79 | C80: =COUNTIF(Database!W:W,CONCATENATE("wc ",B80)) -> 0 | D80: =D79+C80 -> 541 | E80: =D80/533*100 -> 101.50094 | F80: 548 | G80: =IF(D80>=F80,"Yay!","Oh No!") -> Oh No!
A81: 80 | C81: =COUNTIF(Database!W:W,CONCATENATE("wc ",B81)) -> 0 | D81: =D80+C81 -> 541 | E81: =D81/533*100 -> 101.50094 | F81: 548 | G81: =IF(D81>=F81,"Yay!","Oh No!") -> Oh No!
A82: 81 | C82: =COUNTIF(Database!W:W,CONCATENATE("wc ",B82)) -> 0 | D82: =D81+C82 -> 541 | E82: =D82/533*100 -> 101.50094 | F82: 548 | G82: =IF(D82>=F82,"Yay!","Oh No!") -> Oh No!
A83: 82
A84: 83
A85: 84
